Workbook

Sheet 대표 정보
A1: RHEL 계열 9 구성표
A3: No | B3: 항목 | C3: 내용
A4: =ROW()-3 | B4: 자산 ID
A5: =ROW()-3 | B5: 업무·용도
A6: =ROW()-3 | B6: 호스트명 | C6: =IF('구성 확인'!E6="","",'구성 확인'!E6)
A7: =ROW()-3 | B7: 대표 IP
A8: =ROW()-3 | B8: 설치 형태 | C8: =IF('구성 확인'!E17="","",IFERROR(INDEX({"물리","VMware","Hyper-V","KVM","Xen"},MATCH(TRIM('구성 확인'!E17),{"none","vmware","microsoft","kvm","xen"},0)),TRIM('구성 확인'!E17)))
A9: =ROW()-3 | B9: 클러스터
A10: =ROW()-3 | B10: 장비 모델 | C10: =IF('구성 확인'!E15="","",'구성 확인'!E15)
A11: =ROW()-3 | B11: 시리얼번호 | C11: =IF('구성 확인'!E16="","",'구성 확인'!E16)
A12: =ROW()-3 | B12: OS 버전 | C12: =IF('구성 확인'!E7="","",'구성 확인'!E7)
A13: =ROW()-3 | B13: 실행 커널 | C13: =IF('구성 확인'!E9="","",'구성 확인'!E9)
A14: =ROW()-3 | B14: CPU 모델 | C14: =IF('구성 확인'!E18="","",IFERROR(TRIM(MID('구성 확인'!E18,FIND(":",'구성 확인'!E18)+1,200)),'구성 확인'!E18))
A15: =ROW()-3 | B15: CPU 소켓 수 | C15: =IF('구성 확인'!E19="","",'구성 확인'!E19)
A16: =ROW()-3 | B16: 소켓당 코어 수 | C16: =IF('구성 확인'!E20="","",'구성 확인'!E20)
A17: =ROW()-3 | B17: 물리 코어 수 | C17: =IF('구성 확인'!E21="","",'구성 확인'!E21)
A18: =ROW()-3 | B18: 논리 CPU 수 | C18: =IF('구성 확인'!E22="","",'구성 확인'!E22)
A19: =ROW()-3 | B19: 하이퍼스레딩 | C19: =IF('구성 확인'!E23="","",'구성 확인'!E23)
A20: =ROW()-3 | B20: OS 인식 메모리 (MiB) | C20: =IF('구성 확인'!E24="","",'구성 확인'!E24)
A21: =ROW()-3 | B21: 참고

Sheet 구성 확인
A1: RHEL 계열 9 구성 확인 | F1: 수식
B2: 호스트명 | C2: =IF(E6="","",E6) | F2: 해당 없음
B3: 확인일
A5: No | B5: 구분 | C5: 항목 | D5: 명령 | E5: 결과 | F5: 비고
A6: =ROW()-5 | B6: 기본 | C6: 호스트명 | D6: hostname
A7: =ROW()-5 | B7: 기본 | C7: OS 버전 | D7: cat /etc/redhat-release
A8: =ROW()-5 | B8: 기본 | C8: OS 설치일 | D8: stat -c %w / | F8: VM 템플릿 배포는 템플릿 생성일
A9: =ROW()-5 | B9: 기본 | C9: 실행 커널 | D9: uname -r
A10: =ROW()-5 | B10: 기본 | C10: 설치된 커널 | D10: rpm -q kernel | F10: 실행 커널보다 최신이면 재부팅 필요
A11: =ROW()-5 | B11: 기본 | C11: 아키텍처 | D11: uname -m
A12: =ROW()-5 | B12: 기본 | C12: 부팅 방식 | D12: ls /sys/firmware/efi | F12: 경로가 있으면 UEFI
A13: =ROW()-5 | B13: 기본 | C13: 부팅 옵션 | D13: cat /proc/cmdline
A14: =ROW()-5 | B14: 기본 | C14: 마지막 부팅 | D14: who -b
A15: =ROW()-5 | B15: 기본 | C15: 장비 모델 | D15: cat /sys/class/dmi/id/product_name
A16: =ROW()-5 | B16: 기본 | C16: 시리얼번호 | D16: cat /sys/class/dmi/id/product_serial
A17: =ROW()-5 | B17: 기본 | C17: 가상화 | D17: systemd-detect-virt | F17: none이면 물리
A18: =ROW()-5 | B18: CPU·메모리 | C18: CPU 모델 | D18: cat /proc/cpuinfo | grep -i 'model name' | uniq
A19: =ROW()-5 | B19: CPU·메모리 | C19: CPU 소켓 수 | D19: cat /proc/cpuinfo | grep 'physical id' | sort -u | wc -l | F19: 숫자만
A20: =ROW()-5 | B20: CPU·메모리 | C20: 소켓당 코어 수 | D20: cat /proc/cpuinfo | grep -i 'cpu cores' | uniq | F20: 숫자만
A21: =ROW()-5 | B21: CPU·메모리 | C21: 물리 코어 수 | D21: CPU 소켓 수 × 소켓당 코어 수 | E21: =IF(COUNT(E19,E20)=2,E19*E20,"") | F21: 수식
A22: =ROW()-5 | B22: CPU·메모리 | C22: 논리 CPU 수 | D22: cat /proc/cpuinfo | grep -i '^processor' | wc -l | F22: 숫자만
A23: =ROW()-5 | B23: CPU·메모리 | C23: 하이퍼스레딩 | D23: 논리 CPU 수 = 물리 코어 수 × 2 | E23: =IF(COUNT(E21,E22)=2,IF(E22=E21*2,"사용","미사용"),"") | F23: 수식
A24: =ROW()-5 | B24: CPU·메모리 | C24: OS 인식 메모리 (MiB) | D24: free -m | F24: Mem total, 숫자만
A25: =ROW()-5 | B25: CPU·메모리 | C25: 물리 메모리 | D25: dmidecode -t memory | grep -i size | egrep -v 'No Module|Cache|Logical|Volatile' | F25: 물리 서버
A26: =ROW()-5 | B26: CPU·메모리 | C26: GPU | D26: nvidia-smi -L | F26: GPU 서버
A27: =ROW()-5 | B27: 시간 | C27: 시간대 | D27: timedatectl | grep 'Time zone'
A28: =ROW()-5 | B28: 시간 | C28: 시간 동기화 여부 | D28: timedatectl | egrep 'synchronized|NTP'
A29: =ROW()-5 | B29: 시간 | C29: 타임 서버 (chrony) | D29: chronyc sources -v | F29: * 표시가 동기 서버
A30: =ROW()-5 | B30: 네트워크 | C30: IP 주소 | D30: ip -br addr
A31: =ROW()-5 | B31: 네트워크 | C31: MAC 주소 | D31: ip -br link
A32: =ROW()-5 | B32: 네트워크 | C32: MTU | D32: ip link | grep mtu
A33: =ROW()-5 | B33: 네트워크 | C33: 본딩 상태 | D33: tail -v -n +1 /proc/net/bonding/* | F33: 본딩 사용 시
A34: =ROW()-5 | B34: 네트워크 | C34: IPv4 경로 | D34: ip route
A35: =ROW()-5 | B35: 네트워크 | C35: DNS 서버·도메인 | D35: cat /etc/resolv.conf
A36: =ROW()-5 | B36: 네트워크 | C36: 호스트 파일 | D36: cat /etc/hosts
A37: =ROW()-5 | B37: 네트워크 | C37: 네트워크 연결 | D37: nmcli connection show
A38: =ROW()-5 | B38: 네트워크 | C38: 저장된 네트워크 설정 | D38: tail -v -n +1 /etc/NetworkManager/system-connections/*.nmconnection | F38: ifcfg 형식이면 /etc/sysconfig/network-scripts
A39: =ROW()-5 | B39: 네트워크 | C39: 링 버퍼 (RX/TX) | D39: ethtool -g <인터페이스> | F39: 조정한 경우
A40: =ROW()-5 | B40: 디스크 | C40: 장치와 파일시스템 | D40: lsblk -o NAME,TYPE,SIZE,FSTYPE,UUID,MOUNTPOINT,WWN
A41: =ROW()-5 | B41: 디스크 | C41: 파일시스템 사용량 | D41: df -hTl -x tmpfs -x devtmpfs -x overlay -x squashfs
...

Sheet 패키지
A1: 패키지
A3: 원문 | B3: 이름 | C3: 버전 | D3: 릴리스 | E3: 아키텍처 | F3: 설치 일시
B4: =IF($H4="","",LEFT($H4,FIND(" ",$H4&" ")-1)) | C4: =IF($H4="","",IFERROR(MID($H4&" ",FIND("|",SUBSTITUTE($H4&" "," ","|",1))+1,FIND("|",SUBSTITUTE($H4&" "," ","|",2))-FIND("|",SUBSTITUTE($H4&" "," ","|",1))-1),"")) | D4: =IF($H4="","",IFERROR(MID($H4&" ",FIND("|",SUBSTITUTE($H4&" "," ","|",2))+1,FIND("|",SUBSTITUTE($H4&" "," ","|",3))-FIND("|",SUBSTITUTE($H4&" "," ","|",2))-1),"")) | E4: =IF($H4="","",IFERROR(MID($H4&" ",FIND("|",SUBSTITUTE($H4&" "," ","|",3))+1,FIND("|",SUBSTITUTE($H4&" "," ","|",4))-FIND("|",SUBSTITUTE($H4&" "," ","|",3))-1),"")) | F4: =IF($H4="","",IFERROR(VALUE(IFERROR(MID($H4&" ",FIND("|",SUBSTITUTE($H4&" "," ","|",4))+1,FIND("|",SUBSTITUTE($H4&" "," ","|",5))-FIND("|",SUBSTITUTE($H4&" "," ","|",4))-1),""))/86400+25569+9/24,"")) | G4: =TRIM(SUBSTITUTE(SUBSTITUTE(SUBSTITUTE($A4,CHAR(9)," ")," "," "),CHAR(13),"")) | H4: =IF($G4="","",IF(ISNUMBER(FIND(" ",$G4)),$G4,IFERROR(IF((LEN(SUBSTITUTE(SUBSTITUTE($G4,"-"," ",LEN($G4)-LEN(SUBSTITUTE($G4,"-",""))),"-"," ",LEN($G4)-LEN(SUBSTITUTE($G4,"-",""))-1))-LEN(SUBSTITUTE(SUBSTITUTE(SUBSTITUTE($G4,"-"," ",LEN($G4)-LEN(SUBSTITUTE($G4,"-",""))),"-"," ",LEN($G4)-LEN(SUBSTITUTE($G4,"-",""))-1),".","")))=0,SUBSTITUTE(SUBSTITUTE($G4,"-"," ",LEN($G4)-LEN(SUBSTITUTE($G4,"-",""))),"-"," ",LEN($G4)-LEN(SUBSTITUTE($G4,"-",""))-1),SUBSTITUTE(SUBSTITUTE(SUBSTITUTE($G4,"-"," ",LEN($G4)-LEN(SUBSTITUTE($G4,"-",""))),"-"," ",LEN($G4)-LEN(SUBSTITUTE($G4,"-",""))-1),"."," ",(LEN(SUBSTITUTE(SUBSTITUTE($G4,"-"," ",LEN($G4)-LEN(SUBSTITUTE($G4,"-",""))),"-"," ",LEN($G4)-LEN(SUBSTITUTE($G4,"-",""))-1))-LEN(SUBSTITUTE(SUBSTITUTE(SUBSTITUTE($G4,"-"," ",LEN($G4)-LEN(SUBSTITUTE($G4,"-",""))),"-"," ",LEN($G4)-LEN(SUBSTITUTE($G4,"-",""))-1),".",""))))),$G4)))
B5: =IF($H5="","",LEFT($H5,FIND(" ",$H5&" ")-1)) | C5: =IF($H5="","",IFERROR(MID($H5&" ",FIND("|",SUBSTITUTE($H5&" "," ","|",1))+1,FIND("|",SUBSTITUTE($H5&" "," ","|",2))-FIND("|",SUBSTITUTE($H5&" "," ","|",1))-1),"")) | D5: =IF($H5="","",IFERROR(MID($H5&" ",FIND("|",SUBSTITUTE($H5&" "," ","|",2))+1,FIND("|",SUBSTITUTE($H5&" "," ","|",3))-FIND("|",SUBSTITUTE($H5&" "," ","|",2))-1),"")) | E5: =IF($H5="","",IFERROR(MID($H5&" ",FIND("|",SUBSTITUTE($H5&" "," ","|",3))+1,FIND("|",SUBSTITUTE($H5&" "," ","|",4))-FIND("|",SUBSTITUTE($H5&" "," ","|",3))-1),"")) | F5: =IF($H5="","",IFERROR(VALUE(IFERROR(MID($H5&" ",FIND("|",SUBSTITUTE($H5&" "," ","|",4))+1,FIND("|",SUBSTITUTE($H5&" "," ","|",5))-FIND("|",SUBSTITUTE($H5&" "," ","|",4))-1),""))/86400+25569+9/24,"")) | G5: =TRIM(SUBSTITUTE(SUBSTITUTE(SUBSTITUTE($A5,CHAR(9)," ")," "," "),CHAR(13),"")) | H5: =IF($G5="","",IF(ISNUMBER(FIND(" ",$G5)),$G5,IFERROR(IF((LEN(SUBSTITUTE(SUBSTITUTE($G5,"-"," ",LEN($G5)-LEN(SUBSTITUTE($G5,"-",""))),"-"," ",LEN($G5)-LEN(SUBSTITUTE($G5,"-",""))-1))-LEN(SUBSTITUTE(SUBSTITUTE(SUBSTITUTE($G5,"-"," ",LEN($G5)-LEN(SUBSTITUTE($G5,"-",""))),"-"," ",LEN($G5)-LEN(SUBSTITUTE($G5,"-",""))-1),".","")))=0,SUBSTITUTE(SUBSTITUTE($G5,"-"," ",LEN($G5)-LEN(SUBSTITUTE($G5,"-",""))),"-"," ",LEN($G5)-LEN(SUBSTITUTE($G5,"-",""))-1),SUBSTITUTE(SUBSTITUTE(SUBSTITUTE($G5,"-"," ",LEN($G5)-LEN(SUBSTITUTE($G5,"-",""))),"-"," ",LEN($G5)-LEN(SUBSTITUTE($G5,"-",""))-1),"."," ",(LEN(SUBSTITUTE(SUBSTITUTE($G5,"-"," ",LEN($G5)-LEN(SUBSTITUTE($G5,"-",""))),"-"," ",LEN($G5)-LEN(SUBSTITUTE($G5,"-",""))-1))-LEN(SUBSTITUTE(SUBSTITUTE(SUBSTITUTE($G5,"-"," ",LEN($G5)-LEN(SUBSTITUTE($G5,"-",""))),"-"," ",LEN($G5)-LEN(SUBSTITUTE($G5,"-",""))-1),".",""))))),$G5)))
B6: =IF($H6="","",LEFT($H6,FIND(" ",$H6&" ")-1)) | C6: =IF($H6="","",IFERROR(MID($H6&" ",FIND("|",SUBSTITUTE($H6&" "," ","|",1))+1,FIND("|",SUBSTITUTE($H6&" "," ","|",2))-FIND("|",SUBSTITUTE($H6&" "," ","|",1))-1),"")) | D6: =IF($H6="","",IFERROR(MID($H6&" ",FIND("|",SUBSTITUTE($H6&" "," ","|",2))+1,FIND("|",SUBSTITUTE($H6&" "," ","|",3))-FIND("|",SUBSTITUTE($H6&" "," ","|",2))-1),"")) | E6: =IF($H6="","",IFERROR(MID($H6&" ",FIND("|",SUBSTITUTE($H6&" "," ","|",3))+1,FIND("|",SUBSTITUTE($H6&" "," ","|",4))-FIND("|",SUBSTITUTE($H6&" "," ","|",3))-1),"")) | F6: =IF($H6="","",IFERROR(VALUE(IFERROR(MID($H6&" ",FIND("|",SUBSTITUTE($H6&" "," ","|",4))+1,FIND("|",SUBSTITUTE($H6&" "," ","|",5))-FIND("|",SUBSTITUTE($H6&" "," ","|",4))-1),""))/86400+25569+9/24,"")) | G6: =TRIM(SUBSTITUTE(SUBSTITUTE(SUBSTITUTE($A6,CHAR(9)," ")," "," "),CHAR(13),"")) | H6: =IF($G6="","",IF(ISNUMBER(FIND(" ",$G6)),$G6,IFERROR(IF((LEN(SUBSTITUTE(SUBSTITUTE($G6,"-"," ",LEN($G6)-LEN(SUBSTITUTE($G6,"-",""))),"-"," ",LEN($G6)-LEN(SUBSTITUTE($G6,"-",""))-1))-LEN(SUBSTITUTE(SUBSTITUTE(SUBSTITUTE($G6,"-"," ",LEN($G6)-LEN(SUBSTITUTE($G6,"-",""))),"-"," ",LEN($G6)-LEN(SUBSTITUTE($G6,"-",""))-1),".","")))=0,SUBSTITUTE(SUBSTITUTE($G6,"-"," ",LEN($G6)-LEN(SUBSTITUTE($G6,"-",""))),"-"," ",LEN($G6)-LEN(SUBSTITUTE($G6,"-",""))-1),SUBSTITUTE(SUBSTITUTE(SUBSTITUTE($G6,"-"," ",LEN($G6)-LEN(SUBSTITUTE($G6,"-",""))),"-"," ",LEN($G6)-LEN(SUBSTITUTE($G6,"-",""))-1),"."," ",(LEN(SUBSTITUTE(SUBSTITUTE($G6,"-"," ",LEN($G6)-LEN(SUBSTITUTE($G6,"-",""))),"-"," ",LEN($G6)-LEN(SUBSTITUTE($G6,"-",""))-1))-LEN(SUBSTITUTE(SUBSTITUTE(SUBSTITUTE($G6,"-"," ",LEN($G6)-LEN(SUBSTITUTE($G6,"-",""))),"-"," ",LEN($G6)-LEN(SUBSTITUTE($G6,"-",""))-1),".",""))))),$G6)))
B7: =IF($H7="","",LEFT($H7,FIND(" ",$H7&" ")-1)) | C7: =IF($H7="","",IFERROR(MID($H7&" ",FIND("|",SUBSTITUTE($H7&" "," ","|",1))+1,FIND("|",SUBSTITUTE($H7&" "," ","|",2))-FIND("|",SUBSTITUTE($H7&" "," ","|",1))-1),"")) | D7: =IF($H7="","",IFERROR(MID($H7&" ",FIND("|",SUBSTITUTE($H7&" "," ","|",2))+1,FIND("|",SUBSTITUTE($H7&" "," ","|",3))-FIND("|",SUBSTITUTE($H7&" "," ","|",2))-1),"")) | E7: =IF($H7="","",IFERROR(MID($H7&" ",FIND("|",SUBSTITUTE($H7&" "," ","|",3))+1,FIND("|",SUBSTITUTE($H7&" "," ","|",4))-FIND("|",SUBSTITUTE($H7&" "," ","|",3))-1),"")) | F7: =IF($H7="","",IFERROR(VALUE(IFERROR(MID($H7&" ",FIND("|",SUBSTITUTE($H7&" "," ","|",4))+1,FIND("|",SUBSTITUTE($H7&" "," ","|",5))-FIND("|",SUBSTITUTE($H7&" "," ","|",4))-1),""))/86400+25569+9/24,"")) | G7: =TRIM(SUBSTITUTE(SUBSTITUTE(SUBSTITUTE($A7,CHAR(9)," ")," "," "),CHAR(13),"")) | H7: =IF($G7="","",IF(ISNUMBER(FIND(" ",$G7)),$G7,IFERROR(IF((LEN(SUBSTITUTE(SUBSTITUTE($G7,"-"," ",LEN($G7)-LEN(SUBSTITUTE($G7,"-",""))),"-"," ",LEN($G7)-LEN(SUBSTITUTE($G7,"-",""))-1))-LEN(SUBSTITUTE(SUBSTITUTE(SUBSTITUTE($G7,"-"," ",LEN($G7)-LEN(SUBSTITUTE($G7,"-",""))),"-"," ",LEN($G7)-LEN(SUBSTITUTE($G7,"-",""))-1),".","")))=0,SUBSTITUTE(SUBSTITUTE($G7,"-"," ",LEN($G7)-LEN(SUBSTITUTE($G7,"-",""))),"-"," ",LEN($G7)-LEN(SUBSTITUTE($G7,"-",""))-1),SUBSTITUTE(SUBSTITUTE(SUBSTITUTE($G7,"-"," ",LEN($G7)-LEN(SUBSTITUTE($G7,"-",""))),"-"," ",LEN($G7)-LEN(SUBSTITUTE($G7,"-",""))-1),"."," ",(LEN(SUBSTITUTE(SUBSTITUTE($G7,"-"," ",LEN($G7)-LEN(SUBSTITUTE($G7,"-",""))),"-"," ",LEN($G7)-LEN(SUBSTITUTE($G7,"-",""))-1))-LEN(SUBSTITUTE(SUBSTITUTE(SUBSTITUTE($G7,"-"," ",LEN($G7)-LEN(SUBSTITUTE($G7,"-",""))),"-"," ",LEN($G7)-LEN(SUBSTITUTE($G7,"-",""))-1),".",""))))),$G7)))
B8: =IF($H8="","",LEFT($H8,FIND(" ",$H8&" ")-1)) | C8: =IF($H8="","",IFERROR(MID($H8&" ",FIND("|",SUBSTITUTE($H8&" "," ","|",1))+1,FIND("|",SUBSTITUTE($H8&" "," ","|",2))-FIND("|",SUBSTITUTE($H8&" "," ","|",1))-1),"")) | D8: =IF($H8="","",IFERROR(MID($H8&" ",FIND("|",SUBSTITUTE($H8&" "," ","|",2))+1,FIND("|",SUBSTITUTE($H8&" "," ","|",3))-FIND("|",SUBSTITUTE($H8&" "," ","|",2))-1),"")) | E8: =IF($H8="","",IFERROR(MID($H8&" ",FIND("|",SUBSTITUTE($H8&" "," ","|",3))+1,FIND("|",SUBSTITUTE($H8&" "," ","|",4))-FIND("|",SUBSTITUTE($H8&" "," ","|",3))-1),"")) | F8: =IF($H8="","",IFERROR(VALUE(IFERROR(MID($H8&" ",FIND("|",SUBSTITUTE($H8&" "," ","|",4))+1,FIND("|",SUBSTITUTE($H8&" "," ","|",5))-FIND("|",SUBSTITUTE($H8&" "," ","|",4))-1),""))/86400+25569+9/24,"")) | G8: =TRIM(SUBSTITUTE(SUBSTITUTE(SUBSTITUTE($A8,CHAR(9)," ")," "," "),CHAR(13),"")) | H8: =IF($G8="","",IF(ISNUMBER(FIND(" ",$G8)),$G8,IFERROR(IF((LEN(SUBSTITUTE(SUBSTITUTE($G8,"-"," ",LEN($G8)-LEN(SUBSTITUTE($G8,"-",""))),"-"," ",LEN($G8)-LEN(SUBSTITUTE($G8,"-",""))-1))-LEN(SUBSTITUTE(SUBSTITUTE(SUBSTITUTE($G8,"-"," ",LEN($G8)-LEN(SUBSTITUTE($G8,"-",""))),"-"," ",LEN($G8)-LEN(SUBSTITUTE($G8,"-",""))-1),".","")))=0,SUBSTITUTE(SUBSTITUTE($G8,"-"," ",LEN($G8)-LEN(SUBSTITUTE($G8,"-",""))),"-"," ",LEN($G8)-LEN(SUBSTITUTE($G8,"-",""))-1),SUBSTITUTE(SUBSTITUTE(SUBSTITUTE($G8,"-"," ",LEN($G8)-LEN(SUBSTITUTE($G8,"-",""))),"-"," ",LEN($G8)-LEN(SUBSTITUTE($G8,"-",""))-1),"."," ",(LEN(SUBSTITUTE(SUBSTITUTE($G8,"-"," ",LEN($G8)-LEN(SUBSTITUTE($G8,"-",""))),"-"," ",LEN($G8)-LEN(SUBSTITUTE($G8,"-",""))-1))-LEN(SUBSTITUTE(SUBSTITUTE(SUBSTITUTE($G8,"-"," ",LEN($G8)-LEN(SUBSTITUTE($G8,"-",""))),"-"," ",LEN($G8)-LEN(SUBSTITUTE($G8,"-",""))-1),".",""))))),$G8)))
B9: =IF($H9="","",LEFT($H9,FIND(" ",$H9&" ")-1)) | C9: =IF($H9="","",IFERROR(MID($H9&" ",FIND("|",SUBSTITUTE($H9&" "," ","|",1))+1,FIND("|",SUBSTITUTE($H9&" "," ","|",2))-FIND("|",SUBSTITUTE($H9&" "," ","|",1))-1),"")) | D9: =IF($H9="","",IFERROR(MID($H9&" ",FIND("|",SUBSTITUTE($H9&" "," ","|",2))+1,FIND("|",SUBSTITUTE($H9&" "," ","|",3))-FIND("|",SUBSTITUTE($H9&" "," ","|",2))-1),"")) | E9: =IF($H9="","",IFERROR(MID($H9&" ",FIND("|",SUBSTITUTE($H9&" "," ","|",3))+1,FIND("|",SUBSTITUTE($H9&" "," ","|",4))-FIND("|",SUBSTITUTE($H9&" "," ","|",3))-1),"")) | F9: =IF($H9="","",IFERROR(VALUE(IFERROR(MID($H9&" ",FIND("|",SUBSTITUTE($H9&" "," ","|",4))+1,FIND("|",SUBSTITUTE($H9&" "," ","|",5))-FIND("|",SUBSTITUTE($H9&" "," ","|",4))-1),""))/86400+25569+9/24,"")) | G9: =TRIM(SUBSTITUTE(SUBSTITUTE(SUBSTITUTE($A9,CHAR(9)," ")," "," "),CHAR(13),"")) | H9: =IF($G9="","",IF(ISNUMBER(FIND(" ",$G9)),$G9,IFERROR(IF((LEN(SUBSTITUTE(SUBSTITUTE($G9,"-"," ",LEN($G9)-LEN(SUBSTITUTE($G9,"-",""))),"-"," ",LEN($G9)-LEN(SUBSTITUTE($G9,"-",""))-1))-LEN(SUBSTITUTE(SUBSTITUTE(SUBSTITUTE($G9,"-"," ",LEN($G9)-LEN(SUBSTITUTE($G9,"-",""))),"-"," ",LEN($G9)-LEN(SUBSTITUTE($G9,"-",""))-1),".","")))=0,SUBSTITUTE(SUBSTITUTE($G9,"-"," ",LEN($G9)-LEN(SUBSTITUTE($G9,"-",""))),"-"," ",LEN($G9)-LEN(SUBSTITUTE($G9,"-",""))-1),SUBSTITUTE(SUBSTITUTE(SUBSTITUTE($G9,"-"," ",LEN($G9)-LEN(SUBSTITUTE($G9,"-",""))),"-"," ",LEN($G9)-LEN(SUBSTITUTE($G9,"-",""))-1),"."," ",(LEN(SUBSTITUTE(SUBSTITUTE($G9,"-"," ",LEN($G9)-LEN(SUBSTITUTE($G9,"-",""))),"-"," ",LEN($G9)-LEN(SUBSTITUTE($G9,"-",""))-1))-LEN(SUBSTITUTE(SUBSTITUTE(SUBSTITUTE($G9,"-"," ",LEN($G9)-LEN(SUBSTITUTE($G9,"-",""))),"-"," ",LEN($G9)-LEN(SUBSTITUTE($G9,"-",""))-1),".",""))))),$G9)))
B10: =IF($H10="","",LEFT($H10,FIND(" ",$H10&" ")-1)) | C10: =IF($H10="","",IFERROR(MID($H10&" ",FIND("|",SUBSTITUTE($H10&" "," ","|",1))+1,FIND("|",SUBSTITUTE($H10&" "," ","|",2))-FIND("|",SUBSTITUTE($H10&" "," ","|",1))-1),"")) | D10: =IF($H10="","",IFERROR(MID($H10&" ",FIND("|",SUBSTITUTE($H10&" "," ","|",2))+1,FIND("|",SUBSTITUTE($H10&" "," ","|",3))-FIND("|",SUBSTITUTE($H10&" "," ","|",2))-1),"")) | E10: =IF($H10="","",IFERROR(MID($H10&" ",FIND("|",SUBSTITUTE($H10&" "," ","|",3))+1,FIND("|",SUBSTITUTE($H10&" "," ","|",4))-FIND("|",SUBSTITUTE($H10&" "," ","|",3))-1),"")) | F10: =IF($H10="","",IFERROR(VALUE(IFERROR(MID($H10&" ",FIND("|",SUBSTITUTE($H10&" "," ","|",4))+1,FIND("|",SUBSTITUTE($H10&" "," ","|",5))-FIND("|",SUBSTITUTE($H10&" "," ","|",4))-1),""))/86400+25569+9/24,"")) | G10: =TRIM(SUBSTITUTE(SUBSTITUTE(SUBSTITUTE($A10,CHAR(9)," ")," "," "),CHAR(13),"")) | H10: =IF($G10="","",IF(ISNUMBER(FIND(" ",$G10)),$G10,IFERROR(IF((LEN(SUBSTITUTE(SUBSTITUTE($G10,"-"," ",LEN($G10)-LEN(SUBSTITUTE($G10,"-",""))),"-"," ",LEN($G10)-LEN(SUBSTITUTE($G10,"-",""))-1))-LEN(SUBSTITUTE(SUBSTITUTE(SUBSTITUTE($G10,"-"," ",LEN($G10)-LEN(SUBSTITUTE($G10,"-",""))),"-"," ",LEN($G10)-LEN(SUBSTITUTE($G10,"-",""))-1),".","")))=0,SUBSTITUTE(SUBSTITUTE($G10,"-"," ",LEN($G10)-LEN(SUBSTITUTE($G10,"-",""))),"-"," ",LEN($G10)-LEN(SUBSTITUTE($G10,"-",""))-1),SUBSTITUTE(SUBSTITUTE(SUBSTITUTE($G10,"-"," ",LEN($G10)-LEN(SUBSTITUTE($G10,"-",""))),"-"," ",LEN($G10)-LEN(SUBSTITUTE($G10,"-",""))-1),"."," ",(LEN(SUBSTITUTE(SUBSTITUTE($G10,"-"," ",LEN($G10)-LEN(SUBSTITUTE($G10,"-",""))),"-"," ",LEN($G10)-LEN(SUBSTITUTE($G10,"-",""))-1))-LEN(SUBSTITUTE(SUBSTITUTE(SUBSTITUTE($G10,"-"," ",LEN($G10)-LEN(SUBSTITUTE($G10,"-",""))),"-"," ",LEN($G10)-LEN(SUBSTITUTE($G10,"-",""))-1),".",""))))),$G10)))
B11: =IF($H11="","",LEFT($H11,FIND(" ",$H11&" ")-1)) | C11: =IF($H11="","",IFERROR(MID($H11&" ",FIND("|",SUBSTITUTE($H11&" "," ","|",1))+1,FIND("|",SUBSTITUTE($H11&" "," ","|",2))-FIND("|",SUBSTITUTE($H11&" "," ","|",1))-1),"")) | D11: =IF($H11="","",IFERROR(MID($H11&" ",FIND("|",SUBSTITUTE($H11&" "," ","|",2))+1,FIND("|",SUBSTITUTE($H11&" "," ","|",3))-FIND("|",SUBSTITUTE($H11&" "," ","|",2))-1),"")) | E11: =IF($H11="","",IFERROR(MID($H11&" ",FIND("|",SUBSTITUTE($H11&" "," ","|",3))+1,FIND("|",SUBSTITUTE($H11&" "," ","|",4))-FIND("|",SUBSTITUTE($H11&" "," ","|",3))-1),"")) | F11: =IF($H11="","",IFERROR(VALUE(IFERROR(MID($H11&" ",FIND("|",SUBSTITUTE($H11&" "," ","|",4))+1,FIND("|",SUBSTITUTE($H11&" "," ","|",5))-FIND("|",SUBSTITUTE($H11&" "," ","|",4))-1),""))/86400+25569+9/24,"")) | G11: =TRIM(SUBSTITUTE(SUBSTITUTE(SUBSTITUTE($A11,CHAR(9)," ")," "," "),CHAR(13),"")) | H11: =IF($G11="","",IF(ISNUMBER(FIND(" ",$G11)),$G11,IFERROR(IF((LEN(SUBSTITUTE(SUBSTITUTE($G11,"-"," ",LEN($G11)-LEN(SUBSTITUTE($G11,"-",""))),"-"," ",LEN($G11)-LEN(SUBSTITUTE($G11,"-",""))-1))-LEN(SUBSTITUTE(SUBSTITUTE(SUBSTITUTE($G11,"-"," ",LEN($G11)-LEN(SUBSTITUTE($G11,"-",""))),"-"," ",LEN($G11)-LEN(SUBSTITUTE($G11,"-",""))-1),".","")))=0,SUBSTITUTE(SUBSTITUTE($G11,"-"," ",LEN($G11)-LEN(SUBSTITUTE($G11,"-",""))),"-"," ",LEN($G11)-LEN(SUBSTITUTE($G11,"-",""))-1),SUBSTITUTE(SUBSTITUTE(SUBSTITUTE($G11,"-"," ",LEN($G11)-LEN(SUBSTITUTE($G11,"-",""))),"-"," ",LEN($G11)-LEN(SUBSTITUTE($G11,"-",""))-1),"."," ",(LEN(SUBSTITUTE(SUBSTITUTE($G11,"-"," ",LEN($G11)-LEN(SUBSTITUTE($G11,"-",""))),"-"," ",LEN($G11)-LEN(SUBSTITUTE($G11,"-",""))-1))-LEN(SUBSTITUTE(SUBSTITUTE(SUBSTITUTE($G11,"-"," ",LEN($G11)-LEN(SUBSTITUTE($G11,"-",""))),"-"," ",LEN($G11)-LEN(SUBSTITUTE($G11,"-",""))-1),".",""))))),$G11)))
B12: =IF($H12="","",LEFT($H12,FIND(" ",$H12&" ")-1)) | C12: =IF($H12="","",IFERROR(MID($H12&" ",FIND("|",SUBSTITUTE($H12&" "," ","|",1))+1,FIND("|",SUBSTITUTE($H12&" "," ","|",2))-FIND("|",SUBSTITUTE($H12&" "," ","|",1))-1),"")) | D12: =IF($H12="","",IFERROR(MID($H12&" ",FIND("|",SUBSTITUTE($H12&" "," ","|",2))+1,FIND("|",SUBSTITUTE($H12&" "," ","|",3))-FIND("|",SUBSTITUTE($H12&" "," ","|",2))-1),"")) | E12: =IF($H12="","",IFERROR(MID($H12&" ",FIND("|",SUBSTITUTE($H12&" "," ","|",3))+1,FIND("|",SUBSTITUTE($H12&" "," ","|",4))-FIND("|",SUBSTITUTE($H12&" "," ","|",3))-1),"")) | F12: =IF($H12="","",IFERROR(VALUE(IFERROR(MID($H12&" ",FIND("|",SUBSTITUTE($H12&" "," ","|",4))+1,FIND("|",SUBSTITUTE($H12&" "," ","|",5))-FIND("|",SUBSTITUTE($H12&" "," ","|",4))-1),""))/86400+25569+9/24,"")) | G12: =TRIM(SUBSTITUTE(SUBSTITUTE(SUBSTITUTE($A12,CHAR(9)," ")," "," "),CHAR(13),"")) | H12: =IF($G12="","",IF(ISNUMBER(FIND(" ",$G12)),$G12,IFERROR(IF((LEN(SUBSTITUTE(SUBSTITUTE($G12,"-"," ",LEN($G12)-LEN(SUBSTITUTE($G12,"-",""))),"-"," ",LEN($G12)-LEN(SUBSTITUTE($G12,"-",""))-1))-LEN(SUBSTITUTE(SUBSTITUTE(SUBSTITUTE($G12,"-"," ",LEN($G12)-LEN(SUBSTITUTE($G12,"-",""))),"-"," ",LEN($G12)-LEN(SUBSTITUTE($G12,"-",""))-1),".","")))=0,SUBSTITUTE(SUBSTITUTE($G12,"-"," ",LEN($G12)-LEN(SUBSTITUTE($G12,"-",""))),"-"," ",LEN($G12)-LEN(SUBSTITUTE($G12,"-",""))-1),SUBSTITUTE(SUBSTITUTE(SUBSTITUTE($G12,"-"," ",LEN($G12)-LEN(SUBSTITUTE($G12,"-",""))),"-"," ",LEN($G12)-LEN(SUBSTITUTE($G12,"-",""))-1),"."," ",(LEN(SUBSTITUTE(SUBSTITUTE($G12,"-"," ",LEN($G12)-LEN(SUBSTITUTE($G12,"-",""))),"-"," ",LEN($G12)-LEN(SUBSTITUTE($G12,"-",""))-1))-LEN(SUBSTITUTE(SUBSTITUTE(SUBSTITUTE($G12,"-"," ",LEN($G12)-LEN(SUBSTITUTE($G12,"-",""))),"-"," ",LEN($G12)-LEN(SUBSTITUTE($G12,"-",""))-1),".",""))))),$G12)))
B13: =IF($H13="","",LEFT($H13,FIND(" ",$H13&" ")-1)) | C13: =IF($H13="","",IFERROR(MID($H13&" ",FIND("|",SUBSTITUTE($H13&" "," ","|",1))+1,FIND("|",SUBSTITUTE($H13&" "," ","|",2))-FIND("|",SUBSTITUTE($H13&" "," ","|",1))-1),"")) | D13: =IF($H13="","",IFERROR(MID($H13&" ",FIND("|",SUBSTITUTE($H13&" "," ","|",2))+1,FIND("|",SUBSTITUTE($H13&" "," ","|",3))-FIND("|",SUBSTITUTE($H13&" "," ","|",2))-1),"")) | E13: =IF($H13="","",IFERROR(MID($H13&" ",FIND("|",SUBSTITUTE($H13&" "," ","|",3))+1,FIND("|",SUBSTITUTE($H13&" "," ","|",4))-FIND("|",SUBSTITUTE($H13&" "," ","|",3))-1),"")) | F13: =IF($H13="","",IFERROR(VALUE(IFERROR(MID($H13&" ",FIND("|",SUBSTITUTE($H13&" "," ","|",4))+1,FIND("|",SUBSTITUTE($H13&" "," ","|",5))-FIND("|",SUBSTITUTE($H13&" "," ","|",4))-1),""))/86400+25569+9/24,"")) | G13: =TRIM(SUBSTITUTE(SUBSTITUTE(SUBSTITUTE($A13,CHAR(9)," ")," "," "),CHAR(13),"")) | H13: =IF($G13="","",IF(ISNUMBER(FIND(" ",$G13)),$G13,IFERROR(IF((LEN(SUBSTITUTE(SUBSTITUTE($G13,"-"," ",LEN($G13)-LEN(SUBSTITUTE($G13,"-",""))),"-"," ",LEN($G13)-LEN(SUBSTITUTE($G13,"-",""))-1))-LEN(SUBSTITUTE(SUBSTITUTE(SUBSTITUTE($G13,"-"," ",LEN($G13)-LEN(SUBSTITUTE($G13,"-",""))),"-"," ",LEN($G13)-LEN(SUBSTITUTE($G13,"-",""))-1),".","")))=0,SUBSTITUTE(SUBSTITUTE($G13,"-"," ",LEN($G13)-LEN(SUBSTITUTE($G13,"-",""))),"-"," ",LEN($G13)-LEN(SUBSTITUTE($G13,"-",""))-1),SUBSTITUTE(SUBSTITUTE(SUBSTITUTE($G13,"-"," ",LEN($G13)-LEN(SUBSTITUTE($G13,"-",""))),"-"," ",LEN($G13)-LEN(SUBSTITUTE($G13,"-",""))-1),"."," ",(LEN(SUBSTITUTE(SUBSTITUTE($G13,"-"," ",LEN($G13)-LEN(SUBSTITUTE($G13,"-",""))),"-"," ",LEN($G13)-LEN(SUBSTITUTE($G13,"-",""))-1))-LEN(SUBSTITUTE(SUBSTITUTE(SUBSTITUTE($G13,"-"," ",LEN($G13)-LEN(SUBSTITUTE($G13,"-",""))),"-"," ",LEN($G13)-LEN(SUBSTITUTE($G13,"-",""))-1),".",""))))),$G13)))
B14: =IF($H14="","",LEFT($H14,FIND(" ",$H14&" ")-1)) | C14: =IF($H14="","",IFERROR(MID($H14&" ",FIND("|",SUBSTITUTE($H14&" "," ","|",1))+1,FIND("|",SUBSTITUTE($H14&" "," ","|",2))-FIND("|",SUBSTITUTE($H14&" "," ","|",1))-1),"")) | D14: =IF($H14="","",IFERROR(MID($H14&" ",FIND("|",SUBSTITUTE($H14&" "," ","|",2))+1,FIND("|",SUBSTITUTE($H14&" "," ","|",3))-FIND("|",SUBSTITUTE($H14&" "," ","|",2))-1),"")) | E14: =IF($H14="","",IFERROR(MID($H14&" ",FIND("|",SUBSTITUTE($H14&" "," ","|",3))+1,FIND("|",SUBSTITUTE($H14&" "," ","|",4))-FIND("|",SUBSTITUTE($H14&" "," ","|",3))-1),"")) | F14: =IF($H14="","",IFERROR(VALUE(IFERROR(MID($H14&" ",FIND("|",SUBSTITUTE($H14&" "," ","|",4))+1,FIND("|",SUBSTITUTE($H14&" "," ","|",5))-FIND("|",SUBSTITUTE($H14&" "," ","|",4))-1),""))/86400+25569+9/24,"")) | G14: =TRIM(SUBSTITUTE(SUBSTITUTE(SUBSTITUTE($A14,CHAR(9)," ")," "," "),CHAR(13),"")) | H14: =IF($G14="","",IF(ISNUMBER(FIND(" ",$G14)),$G14,IFERROR(IF((LEN(SUBSTITUTE(SUBSTITUTE($G14,"-"," ",LEN($G14)-LEN(SUBSTITUTE($G14,"-",""))),"-"," ",LEN($G14)-LEN(SUBSTITUTE($G14,"-",""))-1))-LEN(SUBSTITUTE(SUBSTITUTE(SUBSTITUTE($G14,"-"," ",LEN($G14)-LEN(SUBSTITUTE($G14,"-",""))),"-"," ",LEN($G14)-LEN(SUBSTITUTE($G14,"-",""))-1),".","")))=0,SUBSTITUTE(SUBSTITUTE($G14,"-"," ",LEN($G14)-LEN(SUBSTITUTE($G14,"-",""))),"-"," ",LEN($G14)-LEN(SUBSTITUTE($G14,"-",""))-1),SUBSTITUTE(SUBSTITUTE(SUBSTITUTE($G14,"-"," ",LEN($G14)-LEN(SUBSTITUTE($G14,"-",""))),"-"," ",LEN($G14)-LEN(SUBSTITUTE($G14,"-",""))-1),"."," ",(LEN(SUBSTITUTE(SUBSTITUTE($G14,"-"," ",LEN($G14)-LEN(SUBSTITUTE($G14,"-",""))),"-"," ",LEN($G14)-LEN(SUBSTITUTE($G14,"-",""))-1))-LEN(SUBSTITUTE(SUBSTITUTE(SUBSTITUTE($G14,"-"," ",LEN($G14)-LEN(SUBSTITUTE($G14,"-",""))),"-"," ",LEN($G14)-LEN(SUBSTITUTE($G14,"-",""))-1),".",""))))),$G14)))
B15: =IF($H15="","",LEFT($H15,FIND(" ",$H15&" ")-1)) | C15: =IF($H15="","",IFERROR(MID($H15&" ",FIND("|",SUBSTITUTE($H15&" "," ","|",1))+1,FIND("|",SUBSTITUTE($H15&" "," ","|",2))-FIND("|",SUBSTITUTE($H15&" "," ","|",1))-1),"")) | D15: =IF($H15="","",IFERROR(MID($H15&" ",FIND("|",SUBSTITUTE($H15&" "," ","|",2))+1,FIND("|",SUBSTITUTE($H15&" "," ","|",3))-FIND("|",SUBSTITUTE($H15&" "," ","|",2))-1),"")) | E15: =IF($H15="","",IFERROR(MID($H15&" ",FIND("|",SUBSTITUTE($H15&" "," ","|",3))+1,FIND("|",SUBSTITUTE($H15&" "," ","|",4))-FIND("|",SUBSTITUTE($H15&" "," ","|",3))-1),"")) | F15: =IF($H15="","",IFERROR(VALUE(IFERROR(MID($H15&" ",FIND("|",SUBSTITUTE($H15&" "," ","|",4))+1,FIND("|",SUBSTITUTE($H15&" "," ","|",5))-FIND("|",SUBSTITUTE($H15&" "," ","|",4))-1),""))/86400+25569+9/24,"")) | G15: =TRIM(SUBSTITUTE(SUBSTITUTE(SUBSTITUTE($A15,CHAR(9)," ")," "," "),CHAR(13),"")) | H15: =IF($G15="","",IF(ISNUMBER(FIND(" ",$G15)),$G15,IFERROR(IF((LEN(SUBSTITUTE(SUBSTITUTE($G15,"-"," ",LEN($G15)-LEN(SUBSTITUTE($G15,"-",""))),"-"," ",LEN($G15)-LEN(SUBSTITUTE($G15,"-",""))-1))-LEN(SUBSTITUTE(SUBSTITUTE(SUBSTITUTE($G15,"-"," ",LEN($G15)-LEN(SUBSTITUTE($G15,"-",""))),"-"," ",LEN($G15)-LEN(SUBSTITUTE($G15,"-",""))-1),".","")))=0,SUBSTITUTE(SUBSTITUTE($G15,"-"," ",LEN($G15)-LEN(SUBSTITUTE($G15,"-",""))),"-"," ",LEN($G15)-LEN(SUBSTITUTE($G15,"-",""))-1),SUBSTITUTE(SUBSTITUTE(SUBSTITUTE($G15,"-"," ",LEN($G15)-LEN(SUBSTITUTE($G15,"-",""))),"-"," ",LEN($G15)-LEN(SUBSTITUTE($G15,"-",""))-1),"."," ",(LEN(SUBSTITUTE(SUBSTITUTE($G15,"-"," ",LEN($G15)-LEN(SUBSTITUTE($G15,"-",""))),"-"," ",LEN($G15)-LEN(SUBSTITUTE($G15,"-",""))-1))-LEN(SUBSTITUTE(SUBSTITUTE(SUBSTITUTE($G15,"-"," ",LEN($G15)-LEN(SUBSTITUTE($G15,"-",""))),"-"," ",LEN($G15)-LEN(SUBSTITUTE($G15,"-",""))-1),".",""))))),$G15)))
... B3003: =IF($H3003="","",LEFT($H3003,FIND(" ",$H3003&" ")-1)) | C3003: =IF($H3003="","",IFERROR(MID($H3003&" ",FIND("|",SUBSTITUTE($H3003&" "," ","|",1))+1,FIND("|",SUBSTITUTE($H3003&" "," ","|",2))-FIND("|",SUBSTITUTE($H3003&" "," ","|",1))-1),"")) | D3003: =IF($H3003="","",IFERROR(MID($H3003&" ",FIND("|",SUBSTITUTE($H3003&" "," ","|",2))+1,FIND("|",SUBSTITUTE($H3003&" "," ","|",3))-FIND("|",SUBSTITUTE($H3003&" "," ","|",2))-1),"")) | E3003: =IF($H3003="","",IFERROR(MID($H3003&" ",FIND("|",SUBSTITUTE($H3003&" "," ","|",3))+1,FIND("|",SUBSTITUTE($H3003&" "," ","|",4))-FIND("|",SUBSTITUTE($H3003&" "," ","|",3))-1),"")) | F3003: =IF($H3003="","",IFERROR(VALUE(IFERROR(MID($H3003&" ",FIND("|",SUBSTITUTE($H3003&" "," ","|",4))+1,FIND("|",SUBSTITUTE($H3003&" "," ","|",5))-FIND("|",SUBSTITUTE($H3003&" "," ","|",4))-1),""))/86400+25569+9/24,"")) | G3003: =TRIM(SUBSTITUTE(SUBSTITUTE(SUBSTITUTE($A3003,CHAR(9)," ")," "," "),CHAR(13),"")) | H3003: =IF($G3003="","",IF(ISNUMBER(FIND(" ",$G3003)),$G3003,IFERROR(IF((LEN(SUBSTITUTE(SUBSTITUTE($G3003,"-"," ",LEN($G3003)-LEN(SUBSTITUTE($G3003,"-",""))),"-"," ",LEN($G3003)-LEN(SUBSTITUTE($G3003,"-",""))-1))-LEN(SUBSTITUTE(SUBSTITUTE(SUBSTITUTE($G3003,"-"," ",LEN($G3003)-LEN(SUBSTITUTE($G3003,"-",""))),"-"," ",LEN($G3003)-LEN(SUBSTITUTE($G3003,"-",""))-1),".","")))=0,SUBSTITUTE(SUBSTITUTE($G3003,"-"," ",LEN($G3003)-LEN(SUBSTITUTE($G3003,"-",""))),"-"," ",LEN($G3003)-LEN(SUBSTITUTE($G3003,"-",""))-1),SUBSTITUTE(SUBSTITUTE(SUBSTITUTE($G3003,"-"," ",LEN($G3003)-LEN(SUBSTITUTE($G3003,"-",""))),"-"," ",LEN($G3003)-LEN(SUBSTITUTE($G3003,"-",""))-1),"."," ",(LEN(SUBSTITUTE(SUBSTITUTE($G3003,"-"," ",LEN($G3003)-LEN(SUBSTITUTE($G3003,"-",""))),"-"," ",LEN($G3003)-LEN(SUBSTITUTE($G3003,"-",""))-1))-LEN(SUBSTITUTE(SUBSTITUTE(SUBSTITUTE($G3003,"-"," ",LEN($G3003)-LEN(SUBSTITUTE($G3003,"-",""))),"-"," ",LEN($G3003)-LEN(SUBSTITUTE($G3003,"-",""))-1),".",""))))),$G3003)))

Sheet 명령 출력
A1: 명령 출력
